{
  "nbformat": 4,
  "nbformat_minor": 0,
  "metadata": {
    "colab": {
      "provenance": [],
      "gpuType": "T4",
      "authorship_tag": "ABX9TyMN+SG8SSm43I1xs3Sir6uY",
      "include_colab_link": true
    },
    "kernelspec": {
      "name": "python3",
      "display_name": "Python 3"
    },
    "language_info": {
      "name": "python"
    },
    "accelerator": "GPU"
  },
  "cells": [
    {
      "cell_type": "markdown",
      "metadata": {
        "id": "view-in-github",
        "colab_type": "text"
      },
      "source": [
        "<a href=\"https://colab.research.google.com/github/MuraliKoushikDesu/MuraliKoushikDesu/blob/main/MuraliKoushikDesu_ICP9.ipynb\" target=\"_parent\"><img src=\"https://colab.research.google.com/assets/colab-badge.svg\" alt=\"Open In Colab\"/></a>"
      ]
    },
    {
      "cell_type": "code",
      "source": [
        "from google.colab import drive\n",
        "drive.mount('/content/drive')"
      ],
      "metadata": {
        "colab": {
          "base_uri": "https://localhost:8080/"
        },
        "id": "Gy6ocGPxk-BH",
        "outputId": "d575f402-2072-462a-f1ad-ebf61b0264e4"
      },
      "execution_count": 1,
      "outputs": [
        {
          "output_type": "stream",
          "name": "stdout",
          "text": [
            "Mounted at /content/drive\n"
          ]
        }
      ]
    },
    {
      "cell_type": "code",
      "source": [
        "!pip install Keras\n",
        "!pip install keras-utils"
      ],
      "metadata": {
        "colab": {
          "base_uri": "https://localhost:8080/"
        },
        "id": "m-YVCxVopp4u",
        "outputId": "ad2bb814-27dc-4a29-cd15-ea02608c95e0"
      },
      "execution_count": 2,
      "outputs": [
        {
          "output_type": "stream",
          "name": "stdout",
          "text": [
            "Requirement already satisfied: Keras in /usr/local/lib/python3.10/dist-packages (2.14.0)\n",
            "Collecting keras-utils\n",
            "  Downloading keras-utils-1.0.13.tar.gz (2.4 kB)\n",
            "  Preparing metadata (setup.py) ... \u001b[?25l\u001b[?25hdone\n",
            "Requirement already satisfied: Keras>=2.1.5 in /usr/local/lib/python3.10/dist-packages (from keras-utils) (2.14.0)\n",
            "Building wheels for collected packages: keras-utils\n",
            "  Building wheel for keras-utils (setup.py) ... \u001b[?25l\u001b[?25hdone\n",
            "  Created wheel for keras-utils: filename=keras_utils-1.0.13-py3-none-any.whl size=2632 sha256=663fa0af3fb1cb31f3dfb078a68f2a34035bd0b5616d5cd8056634b6e86d7e3c\n",
            "  Stored in directory: /root/.cache/pip/wheels/5c/c0/b3/0c332de4fd71f3733ea6d61697464b7ae4b2b5ff0300e6ca7a\n",
            "Successfully built keras-utils\n",
            "Installing collected packages: keras-utils\n",
            "Successfully installed keras-utils-1.0.13\n"
          ]
        }
      ]
    },
    {
      "cell_type": "code",
      "execution_count": 4,
      "metadata": {
        "colab": {
          "base_uri": "https://localhost:8080/"
        },
        "id": "sNdcjybgkaac",
        "outputId": "b59fa191-240e-4055-be69-5f703728a15e"
      },
      "outputs": [
        {
          "output_type": "stream",
          "name": "stderr",
          "text": [
            "WARNING:tensorflow:Layer lstm will not use cuDNN kernels since it doesn't meet the criteria. It will use a generic GPU kernel as fallback when running on GPU.\n"
          ]
        },
        {
          "output_type": "stream",
          "name": "stdout",
          "text": [
            "291/291 - 68s - loss: 0.8204 - accuracy: 0.6462 - 68s/epoch - 235ms/step\n",
            "144/144 - 2s - loss: 0.8034 - accuracy: 0.6638 - 2s/epoch - 16ms/step\n",
            "0.8033743500709534\n",
            "0.6638270020484924\n",
            "['loss', 'accuracy']\n"
          ]
        },
        {
          "output_type": "stream",
          "name": "stderr",
          "text": [
            "/usr/local/lib/python3.10/dist-packages/keras/src/engine/training.py:3079: UserWarning: You are saving your model as an HDF5 file via `model.save()`. This file format is considered legacy. We recommend using instead the native Keras format, e.g. `model.save('my_model.keras')`.\n",
            "  saving_api.save_model(\n"
          ]
        }
      ],
      "source": [
        "import pandas as pd\n",
        "from keras.preprocessing.text import Tokenizer\n",
        "from keras.preprocessing.sequence import pad_sequences\n",
        "from keras.models import Sequential\n",
        "from keras.layers import Dense, Embedding, LSTM, SpatialDropout1D\n",
        "from matplotlib import pyplot\n",
        "from sklearn.model_selection import train_test_split\n",
        "from tensorflow.keras.utils import to_categorical\n",
        "\n",
        "import re\n",
        "\n",
        "from sklearn.preprocessing import LabelEncoder\n",
        "\n",
        "data = pd.read_csv('Sentiment.csv')\n",
        "# Keeping only the neccessary columns\n",
        "data = data[['text','sentiment']]\n",
        "\n",
        "data['text'] = data['text'].apply(lambda x: x.lower())\n",
        "data['text'] = data['text'].apply((lambda x: re.sub('[^a-zA-z0-9\\s]', '', x)))\n",
        "\n",
        "for idx, row in data.iterrows():\n",
        "    row[0] = row[0].replace('rt', ' ')\n",
        "\n",
        "max_fatures = 2000\n",
        "tokenizer = Tokenizer(num_words=max_fatures, split=' ')\n",
        "tokenizer.fit_on_texts(data['text'].values)\n",
        "X = tokenizer.texts_to_sequences(data['text'].values)\n",
        "\n",
        "X = pad_sequences(X)\n",
        "\n",
        "embed_dim = 128\n",
        "lstm_out = 196\n",
        "def createmodel():\n",
        "    model = Sequential()\n",
        "    model.add(Embedding(max_fatures, embed_dim,input_length = X.shape[1]))\n",
        "    model.add(LSTM(lstm_out, dropout=0.2, recurrent_dropout=0.2))\n",
        "    model.add(Dense(3,activation='softmax'))\n",
        "    model.compile(loss = 'categorical_crossentropy', optimizer='adam',metrics = ['accuracy'])\n",
        "    return model\n",
        "# print(model.summary())\n",
        "\n",
        "labelencoder = LabelEncoder()\n",
        "integer_encoded = labelencoder.fit_transform(data['sentiment'])\n",
        "y = to_categorical(integer_encoded)\n",
        "X_train, X_test, Y_train, Y_test = train_test_split(X,y, test_size = 0.33, random_state = 42)\n",
        "\n",
        "batch_size = 32\n",
        "model = createmodel()\n",
        "model.fit(X_train, Y_train, epochs = 1, batch_size=batch_size, verbose = 2)\n",
        "score,acc = model.evaluate(X_test,Y_test,verbose=2,batch_size=batch_size)\n",
        "print(score)\n",
        "print(acc)\n",
        "print(model.metrics_names)\n",
        "\n",
        "# Save the trained model to a file\n",
        "model.save('sentiment_model.h5')"
      ]
    },
    {
      "cell_type": "code",
      "source": [
        "from keras.models import load_model\n",
        "\n",
        "# Load the saved model\n",
        "loaded_model = load_model('sentiment_model.h5')\n",
        "\n",
        "# New text data\n",
        "new_text = [\"A lot of good things are happening. We are respected again throughout the world, and that's a great thing. @realDonaldTrump\"]\n",
        "\n",
        "# Preprocess the new text data\n",
        "new_text = [text.lower() for text in new_text]\n",
        "new_text = [re.sub('[^a-zA-z0-9\\s]', '', text) for text in new_text]\n",
        "new_text_sequences = tokenizer.texts_to_sequences(new_text)\n",
        "new_text_padded = pad_sequences(new_text_sequences, maxlen=X.shape[1])\n",
        "\n",
        "# Make predictions on the new text data\n",
        "predictions = loaded_model.predict(new_text_padded)\n",
        "\n",
        "# Convert predictions to sentiment labels\n",
        "predicted_sentiments = labelencoder.inverse_transform(predictions.argmax(axis=1))\n",
        "\n",
        "# Print the predicted sentiments\n",
        "print(predicted_sentiments)"
      ],
      "metadata": {
        "colab": {
          "base_uri": "https://localhost:8080/"
        },
        "id": "OD5QqQQtX41m",
        "outputId": "0f5b2b93-f487-4404-e333-c22fdb8174c8"
      },
      "execution_count": 5,
      "outputs": [
        {
          "output_type": "stream",
          "name": "stderr",
          "text": [
            "WARNING:tensorflow:Layer lstm will not use cuDNN kernels since it doesn't meet the criteria. It will use a generic GPU kernel as fallback when running on GPU.\n"
          ]
        },
        {
          "output_type": "stream",
          "name": "stdout",
          "text": [
            "1/1 [==============================] - 0s 288ms/step\n",
            "['Negative']\n"
          ]
        }
      ]
    },
    {
      "cell_type": "code",
      "source": [
        "!pip install scikeras"
      ],
      "metadata": {
        "id": "vlCJzzKtZA_4",
        "outputId": "f785d1df-ca87-47ff-cbcd-8efd3034d4d9",
        "colab": {
          "base_uri": "https://localhost:8080/"
        }
      },
      "execution_count": 6,
      "outputs": [
        {
          "output_type": "stream",
          "name": "stdout",
          "text": [
            "Collecting scikeras\n",
            "  Downloading scikeras-0.12.0-py3-none-any.whl (27 kB)\n",
            "Requirement already satisfied: packaging>=0.21 in /usr/local/lib/python3.10/dist-packages (from scikeras) (23.2)\n",
            "Requirement already satisfied: scikit-learn>=1.0.0 in /usr/local/lib/python3.10/dist-packages (from scikeras) (1.2.2)\n",
            "Requirement already satisfied: numpy>=1.17.3 in /usr/local/lib/python3.10/dist-packages (from scikit-learn>=1.0.0->scikeras) (1.23.5)\n",
            "Requirement already satisfied: scipy>=1.3.2 in /usr/local/lib/python3.10/dist-packages (from scikit-learn>=1.0.0->scikeras) (1.11.3)\n",
            "Requirement already satisfied: joblib>=1.1.1 in /usr/local/lib/python3.10/dist-packages (from scikit-learn>=1.0.0->scikeras) (1.3.2)\n",
            "Requirement already satisfied: threadpoolctl>=2.0.0 in /usr/local/lib/python3.10/dist-packages (from scikit-learn>=1.0.0->scikeras) (3.2.0)\n",
            "Installing collected packages: scikeras\n",
            "Successfully installed scikeras-0.12.0\n"
          ]
        }
      ]
    },
    {
      "cell_type": "code",
      "source": [
        "from sklearn.model_selection import GridSearchCV\n",
        "from scikeras.wrappers import KerasClassifier\n",
        "model = KerasClassifier(build_fn=model,verbose=0)\n",
        "batch_size = [10, 20, 40]\n",
        "epochs = [1, 2, 3]\n",
        "param_grid = dict(batch_size=batch_size, epochs=epochs)\n",
        "from sklearn.model_selection import GridSearchCV\n",
        "grid = GridSearchCV(estimator=model, param_grid=param_grid)\n",
        "grid_result = grid.fit(X_train, Y_train)\n",
        "# summarize results\n",
        "print(\"Best: %f using %s\" % (grid_result.best_score_, grid_result.best_params_))"
      ],
      "metadata": {
        "id": "TjTmjniwYNpg",
        "outputId": "62cc39ee-e1e6-444d-c6f0-b304446c6505",
        "colab": {
          "base_uri": "https://localhost:8080/",
          "height": 1000
        }
      },
      "execution_count": 8,
      "outputs": [
        {
          "output_type": "stream",
          "name": "stderr",
          "text": [
            "WARNING:tensorflow:Layer lstm will not use cuDNN kernels since it doesn't meet the criteria. It will use a generic GPU kernel as fallback when running on GPU.\n",
            "WARNING:tensorflow:Layer lstm will not use cuDNN kernels since it doesn't meet the criteria. It will use a generic GPU kernel as fallback when running on GPU.\n",
            "WARNING:tensorflow:Detecting that an object or model or tf.train.Checkpoint is being deleted with unrestored values. See the following logs for the specific values in question. To silence these warnings, use `status.expect_partial()`. See https://www.tensorflow.org/api_docs/python/tf/train/Checkpoint#restorefor details about the status object returned by the restore function.\n",
            "WARNING:tensorflow:Value in checkpoint could not be found in the restored object: (root).keras_api.metrics.0.total\n",
            "WARNING:tensorflow:Value in checkpoint could not be found in the restored object: (root).keras_api.metrics.0.count\n",
            "WARNING:tensorflow:Value in checkpoint could not be found in the restored object: (root).keras_api.metrics.1.total\n",
            "WARNING:tensorflow:Value in checkpoint could not be found in the restored object: (root).keras_api.metrics.1.count\n",
            "/usr/local/lib/python3.10/dist-packages/scikeras/wrappers.py:915: UserWarning: ``build_fn`` will be renamed to ``model`` in a future release, at which point use of ``build_fn`` will raise an Error instead.\n",
            "  X, y = self._initialize(X, y)\n",
            "WARNING:tensorflow:Layer lstm will not use cuDNN kernels since it doesn't meet the criteria. It will use a generic GPU kernel as fallback when running on GPU.\n",
            "/usr/local/lib/python3.10/dist-packages/scikeras/wrappers.py:915: UserWarning: ``build_fn`` will be renamed to ``model`` in a future release, at which point use of ``build_fn`` will raise an Error instead.\n",
            "  X, y = self._initialize(X, y)\n",
            "WARNING:tensorflow:Layer lstm will not use cuDNN kernels since it doesn't meet the criteria. It will use a generic GPU kernel as fallback when running on GPU.\n",
            "/usr/local/lib/python3.10/dist-packages/scikeras/wrappers.py:915: UserWarning: ``build_fn`` will be renamed to ``model`` in a future release, at which point use of ``build_fn`` will raise an Error instead.\n",
            "  X, y = self._initialize(X, y)\n",
            "WARNING:tensorflow:Detecting that an object or model or tf.train.Checkpoint is being deleted with unrestored values. See the following logs for the specific values in question. To silence these warnings, use `status.expect_partial()`. See https://www.tensorflow.org/api_docs/python/tf/train/Checkpoint#restorefor details about the status object returned by the restore function.\n",
            "WARNING:tensorflow:Value in checkpoint could not be found in the restored object: (root).keras_api.metrics.0.total\n",
            "WARNING:tensorflow:Value in checkpoint could not be found in the restored object: (root).keras_api.metrics.0.count\n",
            "WARNING:tensorflow:Value in checkpoint could not be found in the restored object: (root).keras_api.metrics.1.total\n",
            "WARNING:tensorflow:Value in checkpoint could not be found in the restored object: (root).keras_api.metrics.1.count\n",
            "WARNING:tensorflow:Detecting that an object or model or tf.train.Checkpoint is being deleted with unrestored values. See the following logs for the specific values in question. To silence these warnings, use `status.expect_partial()`. See https://www.tensorflow.org/api_docs/python/tf/train/Checkpoint#restorefor details about the status object returned by the restore function.\n",
            "WARNING:tensorflow:Value in checkpoint could not be found in the restored object: (root).keras_api.metrics.0.total\n",
            "WARNING:tensorflow:Value in checkpoint could not be found in the restored object: (root).keras_api.metrics.0.count\n",
            "WARNING:tensorflow:Value in checkpoint could not be found in the restored object: (root).keras_api.metrics.1.total\n",
            "WARNING:tensorflow:Value in checkpoint could not be found in the restored object: (root).keras_api.metrics.1.count\n",
            "WARNING:tensorflow:Layer lstm will not use cuDNN kernels since it doesn't meet the criteria. It will use a generic GPU kernel as fallback when running on GPU.\n",
            "/usr/local/lib/python3.10/dist-packages/scikeras/wrappers.py:915: UserWarning: ``build_fn`` will be renamed to ``model`` in a future release, at which point use of ``build_fn`` will raise an Error instead.\n",
            "  X, y = self._initialize(X, y)\n",
            "WARNING:tensorflow:Layer lstm will not use cuDNN kernels since it doesn't meet the criteria. It will use a generic GPU kernel as fallback when running on GPU.\n",
            "/usr/local/lib/python3.10/dist-packages/scikeras/wrappers.py:915: UserWarning: ``build_fn`` will be renamed to ``model`` in a future release, at which point use of ``build_fn`` will raise an Error instead.\n",
            "  X, y = self._initialize(X, y)\n",
            "WARNING:tensorflow:Layer lstm will not use cuDNN kernels since it doesn't meet the criteria. It will use a generic GPU kernel as fallback when running on GPU.\n",
            "/usr/local/lib/python3.10/dist-packages/scikeras/wrappers.py:915: UserWarning: ``build_fn`` will be renamed to ``model`` in a future release, at which point use of ``build_fn`` will raise an Error instead.\n",
            "  X, y = self._initialize(X, y)\n",
            "WARNING:tensorflow:Detecting that an object or model or tf.train.Checkpoint is being deleted with unrestored values. See the following logs for the specific values in question. To silence these warnings, use `status.expect_partial()`. See https://www.tensorflow.org/api_docs/python/tf/train/Checkpoint#restorefor details about the status object returned by the restore function.\n",
            "WARNING:tensorflow:Value in checkpoint could not be found in the restored object: (root).keras_api.metrics.0.total\n",
            "WARNING:tensorflow:Value in checkpoint could not be found in the restored object: (root).keras_api.metrics.0.count\n",
            "WARNING:tensorflow:Value in checkpoint could not be found in the restored object: (root).keras_api.metrics.1.total\n",
            "WARNING:tensorflow:Value in checkpoint could not be found in the restored object: (root).keras_api.metrics.1.count\n",
            "WARNING:tensorflow:Detecting that an object or model or tf.train.Checkpoint is being deleted with unrestored values. See the following logs for the specific values in question. To silence these warnings, use `status.expect_partial()`. See https://www.tensorflow.org/api_docs/python/tf/train/Checkpoint#restorefor details about the status object returned by the restore function.\n",
            "WARNING:tensorflow:Value in checkpoint could not be found in the restored object: (root).keras_api.metrics.0.total\n",
            "WARNING:tensorflow:Value in checkpoint could not be found in the restored object: (root).keras_api.metrics.0.count\n",
            "WARNING:tensorflow:Value in checkpoint could not be found in the restored object: (root).keras_api.metrics.1.total\n",
            "WARNING:tensorflow:Value in checkpoint could not be found in the restored object: (root).keras_api.metrics.1.count\n",
            "WARNING:tensorflow:Detecting that an object or model or tf.train.Checkpoint is being deleted with unrestored values. See the following logs for the specific values in question. To silence these warnings, use `status.expect_partial()`. See https://www.tensorflow.org/api_docs/python/tf/train/Checkpoint#restorefor details about the status object returned by the restore function.\n",
            "WARNING:tensorflow:Value in checkpoint could not be found in the restored object: (root).keras_api.metrics.0.total\n",
            "WARNING:tensorflow:Value in checkpoint could not be found in the restored object: (root).keras_api.metrics.0.count\n",
            "WARNING:tensorflow:Value in checkpoint could not be found in the restored object: (root).keras_api.metrics.1.total\n",
            "WARNING:tensorflow:Value in checkpoint could not be found in the restored object: (root).keras_api.metrics.1.count\n",
            "WARNING:tensorflow:Layer lstm will not use cuDNN kernels since it doesn't meet the criteria. It will use a generic GPU kernel as fallback when running on GPU.\n",
            "/usr/local/lib/python3.10/dist-packages/scikeras/wrappers.py:915: UserWarning: ``build_fn`` will be renamed to ``model`` in a future release, at which point use of ``build_fn`` will raise an Error instead.\n",
            "  X, y = self._initialize(X, y)\n",
            "WARNING:tensorflow:Layer lstm will not use cuDNN kernels since it doesn't meet the criteria. It will use a generic GPU kernel as fallback when running on GPU.\n",
            "/usr/local/lib/python3.10/dist-packages/scikeras/wrappers.py:915: UserWarning: ``build_fn`` will be renamed to ``model`` in a future release, at which point use of ``build_fn`` will raise an Error instead.\n",
            "  X, y = self._initialize(X, y)\n",
            "WARNING:tensorflow:Layer lstm will not use cuDNN kernels since it doesn't meet the criteria. It will use a generic GPU kernel as fallback when running on GPU.\n",
            "WARNING:tensorflow:Detecting that an object or model or tf.train.Checkpoint is being deleted with unrestored values. See the following logs for the specific values in question. To silence these warnings, use `status.expect_partial()`. See https://www.tensorflow.org/api_docs/python/tf/train/Checkpoint#restorefor details about the status object returned by the restore function.\n",
            "WARNING:tensorflow:Value in checkpoint could not be found in the restored object: (root).keras_api.metrics.0.total\n",
            "WARNING:tensorflow:Value in checkpoint could not be found in the restored object: (root).keras_api.metrics.0.count\n",
            "WARNING:tensorflow:Value in checkpoint could not be found in the restored object: (root).keras_api.metrics.1.total\n",
            "WARNING:tensorflow:Value in checkpoint could not be found in the restored object: (root).keras_api.metrics.1.count\n",
            "WARNING:tensorflow:Detecting that an object or model or tf.train.Checkpoint is being deleted with unrestored values. See the following logs for the specific values in question. To silence these warnings, use `status.expect_partial()`. See https://www.tensorflow.org/api_docs/python/tf/train/Checkpoint#restorefor details about the status object returned by the restore function.\n",
            "WARNING:tensorflow:Value in checkpoint could not be found in the restored object: (root).keras_api.metrics.0.total\n",
            "WARNING:tensorflow:Value in checkpoint could not be found in the restored object: (root).keras_api.metrics.0.count\n",
            "WARNING:tensorflow:Value in checkpoint could not be found in the restored object: (root).keras_api.metrics.1.total\n",
            "WARNING:tensorflow:Value in checkpoint could not be found in the restored object: (root).keras_api.metrics.1.count\n",
            "/usr/local/lib/python3.10/dist-packages/scikeras/wrappers.py:915: UserWarning: ``build_fn`` will be renamed to ``model`` in a future release, at which point use of ``build_fn`` will raise an Error instead.\n",
            "  X, y = self._initialize(X, y)\n",
            "WARNING:tensorflow:Layer lstm will not use cuDNN kernels since it doesn't meet the criteria. It will use a generic GPU kernel as fallback when running on GPU.\n",
            "/usr/local/lib/python3.10/dist-packages/scikeras/wrappers.py:915: UserWarning: ``build_fn`` will be renamed to ``model`` in a future release, at which point use of ``build_fn`` will raise an Error instead.\n",
            "  X, y = self._initialize(X, y)\n",
            "WARNING:tensorflow:Layer lstm will not use cuDNN kernels since it doesn't meet the criteria. It will use a generic GPU kernel as fallback when running on GPU.\n",
            "/usr/local/lib/python3.10/dist-packages/scikeras/wrappers.py:915: UserWarning: ``build_fn`` will be renamed to ``model`` in a future release, at which point use of ``build_fn`` will raise an Error instead.\n",
            "  X, y = self._initialize(X, y)\n",
            "WARNING:tensorflow:Layer lstm will not use cuDNN kernels since it doesn't meet the criteria. It will use a generic GPU kernel as fallback when running on GPU.\n",
            "WARNING:tensorflow:Detecting that an object or model or tf.train.Checkpoint is being deleted with unrestored values. See the following logs for the specific values in question. To silence these warnings, use `status.expect_partial()`. See https://www.tensorflow.org/api_docs/python/tf/train/Checkpoint#restorefor details about the status object returned by the restore function.\n",
            "WARNING:tensorflow:Value in checkpoint could not be found in the restored object: (root).keras_api.metrics.0.total\n",
            "WARNING:tensorflow:Value in checkpoint could not be found in the restored object: (root).keras_api.metrics.0.count\n",
            "WARNING:tensorflow:Value in checkpoint could not be found in the restored object: (root).keras_api.metrics.1.total\n",
            "WARNING:tensorflow:Value in checkpoint could not be found in the restored object: (root).keras_api.metrics.1.count\n",
            "WARNING:tensorflow:Detecting that an object or model or tf.train.Checkpoint is being deleted with unrestored values. See the following logs for the specific values in question. To silence these warnings, use `status.expect_partial()`. See https://www.tensorflow.org/api_docs/python/tf/train/Checkpoint#restorefor details about the status object returned by the restore function.\n",
            "WARNING:tensorflow:Value in checkpoint could not be found in the restored object: (root).keras_api.metrics.0.total\n",
            "WARNING:tensorflow:Value in checkpoint could not be found in the restored object: (root).keras_api.metrics.0.count\n",
            "WARNING:tensorflow:Value in checkpoint could not be found in the restored object: (root).keras_api.metrics.1.total\n",
            "WARNING:tensorflow:Value in checkpoint could not be found in the restored object: (root).keras_api.metrics.1.count\n",
            "WARNING:tensorflow:Detecting that an object or model or tf.train.Checkpoint is being deleted with unrestored values. See the following logs for the specific values in question. To silence these warnings, use `status.expect_partial()`. See https://www.tensorflow.org/api_docs/python/tf/train/Checkpoint#restorefor details about the status object returned by the restore function.\n",
            "WARNING:tensorflow:Value in checkpoint could not be found in the restored object: (root).keras_api.metrics.0.total\n",
            "WARNING:tensorflow:Value in checkpoint could not be found in the restored object: (root).keras_api.metrics.0.count\n",
            "WARNING:tensorflow:Value in checkpoint could not be found in the restored object: (root).keras_api.metrics.1.total\n",
            "WARNING:tensorflow:Value in checkpoint could not be found in the restored object: (root).keras_api.metrics.1.count\n",
            "/usr/local/lib/python3.10/dist-packages/scikeras/wrappers.py:915: UserWarning: ``build_fn`` will be renamed to ``model`` in a future release, at which point use of ``build_fn`` will raise an Error instead.\n",
            "  X, y = self._initialize(X, y)\n",
            "WARNING:tensorflow:Layer lstm will not use cuDNN kernels since it doesn't meet the criteria. It will use a generic GPU kernel as fallback when running on GPU.\n",
            "/usr/local/lib/python3.10/dist-packages/scikeras/wrappers.py:915: UserWarning: ``build_fn`` will be renamed to ``model`` in a future release, at which point use of ``build_fn`` will raise an Error instead.\n",
            "  X, y = self._initialize(X, y)\n",
            "WARNING:tensorflow:Layer lstm will not use cuDNN kernels since it doesn't meet the criteria. It will use a generic GPU kernel as fallback when running on GPU.\n",
            "/usr/local/lib/python3.10/dist-packages/scikeras/wrappers.py:915: UserWarning: ``build_fn`` will be renamed to ``model`` in a future release, at which point use of ``build_fn`` will raise an Error instead.\n",
            "  X, y = self._initialize(X, y)\n",
            "WARNING:tensorflow:Detecting that an object or model or tf.train.Checkpoint is being deleted with unrestored values. See the following logs for the specific values in question. To silence these warnings, use `status.expect_partial()`. See https://www.tensorflow.org/api_docs/python/tf/train/Checkpoint#restorefor details about the status object returned by the restore function.\n",
            "WARNING:tensorflow:Value in checkpoint could not be found in the restored object: (root).keras_api.metrics.0.total\n",
            "WARNING:tensorflow:Value in checkpoint could not be found in the restored object: (root).keras_api.metrics.0.count\n",
            "WARNING:tensorflow:Value in checkpoint could not be found in the restored object: (root).keras_api.metrics.1.total\n",
            "WARNING:tensorflow:Value in checkpoint could not be found in the restored object: (root).keras_api.metrics.1.count\n",
            "WARNING:tensorflow:Detecting that an object or model or tf.train.Checkpoint is being deleted with unrestored values. See the following logs for the specific values in question. To silence these warnings, use `status.expect_partial()`. See https://www.tensorflow.org/api_docs/python/tf/train/Checkpoint#restorefor details about the status object returned by the restore function.\n",
            "WARNING:tensorflow:Value in checkpoint could not be found in the restored object: (root).keras_api.metrics.0.total\n",
            "WARNING:tensorflow:Value in checkpoint could not be found in the restored object: (root).keras_api.metrics.0.count\n",
            "WARNING:tensorflow:Value in checkpoint could not be found in the restored object: (root).keras_api.metrics.1.total\n",
            "WARNING:tensorflow:Value in checkpoint could not be found in the restored object: (root).keras_api.metrics.1.count\n",
            "WARNING:tensorflow:Detecting that an object or model or tf.train.Checkpoint is being deleted with unrestored values. See the following logs for the specific values in question. To silence these warnings, use `status.expect_partial()`. See https://www.tensorflow.org/api_docs/python/tf/train/Checkpoint#restorefor details about the status object returned by the restore function.\n",
            "WARNING:tensorflow:Value in checkpoint could not be found in the restored object: (root).keras_api.metrics.0.total\n",
            "WARNING:tensorflow:Value in checkpoint could not be found in the restored object: (root).keras_api.metrics.0.count\n",
            "WARNING:tensorflow:Value in checkpoint could not be found in the restored object: (root).keras_api.metrics.1.total\n",
            "WARNING:tensorflow:Value in checkpoint could not be found in the restored object: (root).keras_api.metrics.1.count\n",
            "WARNING:tensorflow:Layer lstm will not use cuDNN kernels since it doesn't meet the criteria. It will use a generic GPU kernel as fallback when running on GPU.\n",
            "/usr/local/lib/python3.10/dist-packages/scikeras/wrappers.py:915: UserWarning: ``build_fn`` will be renamed to ``model`` in a future release, at which point use of ``build_fn`` will raise an Error instead.\n",
            "  X, y = self._initialize(X, y)\n",
            "WARNING:tensorflow:Layer lstm will not use cuDNN kernels since it doesn't meet the criteria. It will use a generic GPU kernel as fallback when running on GPU.\n",
            "/usr/local/lib/python3.10/dist-packages/scikeras/wrappers.py:915: UserWarning: ``build_fn`` will be renamed to ``model`` in a future release, at which point use of ``build_fn`` will raise an Error instead.\n",
            "  X, y = self._initialize(X, y)\n",
            "WARNING:tensorflow:Layer lstm will not use cuDNN kernels since it doesn't meet the criteria. It will use a generic GPU kernel as fallback when running on GPU.\n",
            "/usr/local/lib/python3.10/dist-packages/scikeras/wrappers.py:915: UserWarning: ``build_fn`` will be renamed to ``model`` in a future release, at which point use of ``build_fn`` will raise an Error instead.\n",
            "  X, y = self._initialize(X, y)\n",
            "WARNING:tensorflow:Detecting that an object or model or tf.train.Checkpoint is being deleted with unrestored values. See the following logs for the specific values in question. To silence these warnings, use `status.expect_partial()`. See https://www.tensorflow.org/api_docs/python/tf/train/Checkpoint#restorefor details about the status object returned by the restore function.\n",
            "WARNING:tensorflow:Value in checkpoint could not be found in the restored object: (root).keras_api.metrics.0.total\n",
            "WARNING:tensorflow:Value in checkpoint could not be found in the restored object: (root).keras_api.metrics.0.count\n",
            "WARNING:tensorflow:Value in checkpoint could not be found in the restored object: (root).keras_api.metrics.1.total\n",
            "WARNING:tensorflow:Value in checkpoint could not be found in the restored object: (root).keras_api.metrics.1.count\n",
            "WARNING:tensorflow:Detecting that an object or model or tf.train.Checkpoint is being deleted with unrestored values. See the following logs for the specific values in question. To silence these warnings, use `status.expect_partial()`. See https://www.tensorflow.org/api_docs/python/tf/train/Checkpoint#restorefor details about the status object returned by the restore function.\n",
            "WARNING:tensorflow:Value in checkpoint could not be found in the restored object: (root).keras_api.metrics.0.total\n",
            "WARNING:tensorflow:Value in checkpoint could not be found in the restored object: (root).keras_api.metrics.0.count\n",
            "WARNING:tensorflow:Value in checkpoint could not be found in the restored object: (root).keras_api.metrics.1.total\n",
            "WARNING:tensorflow:Value in checkpoint could not be found in the restored object: (root).keras_api.metrics.1.count\n",
            "WARNING:tensorflow:Detecting that an object or model or tf.train.Checkpoint is being deleted with unrestored values. See the following logs for the specific values in question. To silence these warnings, use `status.expect_partial()`. See https://www.tensorflow.org/api_docs/python/tf/train/Checkpoint#restorefor details about the status object returned by the restore function.\n",
            "WARNING:tensorflow:Value in checkpoint could not be found in the restored object: (root).keras_api.metrics.0.total\n",
            "WARNING:tensorflow:Value in checkpoint could not be found in the restored object: (root).keras_api.metrics.0.count\n",
            "WARNING:tensorflow:Value in checkpoint could not be found in the restored object: (root).keras_api.metrics.1.total\n",
            "WARNING:tensorflow:Value in checkpoint could not be found in the restored object: (root).keras_api.metrics.1.count\n",
            "WARNING:tensorflow:Layer lstm will not use cuDNN kernels since it doesn't meet the criteria. It will use a generic GPU kernel as fallback when running on GPU.\n",
            "/usr/local/lib/python3.10/dist-packages/scikeras/wrappers.py:915: UserWarning: ``build_fn`` will be renamed to ``model`` in a future release, at which point use of ``build_fn`` will raise an Error instead.\n",
            "  X, y = self._initialize(X, y)\n",
            "WARNING:tensorflow:Layer lstm will not use cuDNN kernels since it doesn't meet the criteria. It will use a generic GPU kernel as fallback when running on GPU.\n",
            "/usr/local/lib/python3.10/dist-packages/scikeras/wrappers.py:915: UserWarning: ``build_fn`` will be renamed to ``model`` in a future release, at which point use of ``build_fn`` will raise an Error instead.\n",
            "  X, y = self._initialize(X, y)\n",
            "WARNING:tensorflow:Layer lstm will not use cuDNN kernels since it doesn't meet the criteria. It will use a generic GPU kernel as fallback when running on GPU.\n",
            "WARNING:tensorflow:Detecting that an object or model or tf.train.Checkpoint is being deleted with unrestored values. See the following logs for the specific values in question. To silence these warnings, use `status.expect_partial()`. See https://www.tensorflow.org/api_docs/python/tf/train/Checkpoint#restorefor details about the status object returned by the restore function.\n",
            "WARNING:tensorflow:Value in checkpoint could not be found in the restored object: (root).keras_api.metrics.0.total\n",
            "WARNING:tensorflow:Value in checkpoint could not be found in the restored object: (root).keras_api.metrics.0.count\n",
            "WARNING:tensorflow:Value in checkpoint could not be found in the restored object: (root).keras_api.metrics.1.total\n",
            "WARNING:tensorflow:Value in checkpoint could not be found in the restored object: (root).keras_api.metrics.1.count\n",
            "WARNING:tensorflow:Detecting that an object or model or tf.train.Checkpoint is being deleted with unrestored values. See the following logs for the specific values in question. To silence these warnings, use `status.expect_partial()`. See https://www.tensorflow.org/api_docs/python/tf/train/Checkpoint#restorefor details about the status object returned by the restore function.\n",
            "WARNING:tensorflow:Value in checkpoint could not be found in the restored object: (root).keras_api.metrics.0.total\n",
            "WARNING:tensorflow:Value in checkpoint could not be found in the restored object: (root).keras_api.metrics.0.count\n",
            "WARNING:tensorflow:Value in checkpoint could not be found in the restored object: (root).keras_api.metrics.1.total\n",
            "WARNING:tensorflow:Value in checkpoint could not be found in the restored object: (root).keras_api.metrics.1.count\n",
            "/usr/local/lib/python3.10/dist-packages/scikeras/wrappers.py:915: UserWarning: ``build_fn`` will be renamed to ``model`` in a future release, at which point use of ``build_fn`` will raise an Error instead.\n",
            "  X, y = self._initialize(X, y)\n",
            "WARNING:tensorflow:Layer lstm will not use cuDNN kernels since it doesn't meet the criteria. It will use a generic GPU kernel as fallback when running on GPU.\n",
            "/usr/local/lib/python3.10/dist-packages/scikeras/wrappers.py:915: UserWarning: ``build_fn`` will be renamed to ``model`` in a future release, at which point use of ``build_fn`` will raise an Error instead.\n",
            "  X, y = self._initialize(X, y)\n",
            "WARNING:tensorflow:Layer lstm will not use cuDNN kernels since it doesn't meet the criteria. It will use a generic GPU kernel as fallback when running on GPU.\n",
            "/usr/local/lib/python3.10/dist-packages/scikeras/wrappers.py:915: UserWarning: ``build_fn`` will be renamed to ``model`` in a future release, at which point use of ``build_fn`` will raise an Error instead.\n",
            "  X, y = self._initialize(X, y)\n",
            "WARNING:tensorflow:Detecting that an object or model or tf.train.Checkpoint is being deleted with unrestored values. See the following logs for the specific values in question. To silence these warnings, use `status.expect_partial()`. See https://www.tensorflow.org/api_docs/python/tf/train/Checkpoint#restorefor details about the status object returned by the restore function.\n",
            "WARNING:tensorflow:Value in checkpoint could not be found in the restored object: (root).keras_api.metrics.0.total\n",
            "WARNING:tensorflow:Value in checkpoint could not be found in the restored object: (root).keras_api.metrics.0.count\n",
            "WARNING:tensorflow:Value in checkpoint could not be found in the restored object: (root).keras_api.metrics.1.total\n",
            "WARNING:tensorflow:Value in checkpoint could not be found in the restored object: (root).keras_api.metrics.1.count\n",
            "WARNING:tensorflow:Detecting that an object or model or tf.train.Checkpoint is being deleted with unrestored values. See the following logs for the specific values in question. To silence these warnings, use `status.expect_partial()`. See https://www.tensorflow.org/api_docs/python/tf/train/Checkpoint#restorefor details about the status object returned by the restore function.\n",
            "WARNING:tensorflow:Value in checkpoint could not be found in the restored object: (root).keras_api.metrics.0.total\n",
            "WARNING:tensorflow:Value in checkpoint could not be found in the restored object: (root).keras_api.metrics.0.count\n",
            "WARNING:tensorflow:Value in checkpoint could not be found in the restored object: (root).keras_api.metrics.1.total\n",
            "WARNING:tensorflow:Value in checkpoint could not be found in the restored object: (root).keras_api.metrics.1.count\n",
            "WARNING:tensorflow:Detecting that an object or model or tf.train.Checkpoint is being deleted with unrestored values. See the following logs for the specific values in question. To silence these warnings, use `status.expect_partial()`. See https://www.tensorflow.org/api_docs/python/tf/train/Checkpoint#restorefor details about the status object returned by the restore function.\n",
            "WARNING:tensorflow:Value in checkpoint could not be found in the restored object: (root).keras_api.metrics.0.total\n",
            "WARNING:tensorflow:Value in checkpoint could not be found in the restored object: (root).keras_api.metrics.0.count\n",
            "WARNING:tensorflow:Value in checkpoint could not be found in the restored object: (root).keras_api.metrics.1.total\n",
            "WARNING:tensorflow:Value in checkpoint could not be found in the restored object: (root).keras_api.metrics.1.count\n",
            "WARNING:tensorflow:Layer lstm will not use cuDNN kernels since it doesn't meet the criteria. It will use a generic GPU kernel as fallback when running on GPU.\n",
            "/usr/local/lib/python3.10/dist-packages/scikeras/wrappers.py:915: UserWarning: ``build_fn`` will be renamed to ``model`` in a future release, at which point use of ``build_fn`` will raise an Error instead.\n",
            "  X, y = self._initialize(X, y)\n",
            "WARNING:tensorflow:Layer lstm will not use cuDNN kernels since it doesn't meet the criteria. It will use a generic GPU kernel as fallback when running on GPU.\n",
            "/usr/local/lib/python3.10/dist-packages/scikeras/wrappers.py:915: UserWarning: ``build_fn`` will be renamed to ``model`` in a future release, at which point use of ``build_fn`` will raise an Error instead.\n",
            "  X, y = self._initialize(X, y)\n",
            "WARNING:tensorflow:Layer lstm will not use cuDNN kernels since it doesn't meet the criteria. It will use a generic GPU kernel as fallback when running on GPU.\n",
            "/usr/local/lib/python3.10/dist-packages/scikeras/wrappers.py:915: UserWarning: ``build_fn`` will be renamed to ``model`` in a future release, at which point use of ``build_fn`` will raise an Error instead.\n",
            "  X, y = self._initialize(X, y)\n",
            "WARNING:tensorflow:Detecting that an object or model or tf.train.Checkpoint is being deleted with unrestored values. See the following logs for the specific values in question. To silence these warnings, use `status.expect_partial()`. See https://www.tensorflow.org/api_docs/python/tf/train/Checkpoint#restorefor details about the status object returned by the restore function.\n",
            "WARNING:tensorflow:Value in checkpoint could not be found in the restored object: (root).keras_api.metrics.0.total\n",
            "WARNING:tensorflow:Value in checkpoint could not be found in the restored object: (root).keras_api.metrics.0.count\n",
            "WARNING:tensorflow:Value in checkpoint could not be found in the restored object: (root).keras_api.metrics.1.total\n",
            "WARNING:tensorflow:Value in checkpoint could not be found in the restored object: (root).keras_api.metrics.1.count\n",
            "WARNING:tensorflow:Detecting that an object or model or tf.train.Checkpoint is being deleted with unrestored values. See the following logs for the specific values in question. To silence these warnings, use `status.expect_partial()`. See https://www.tensorflow.org/api_docs/python/tf/train/Checkpoint#restorefor details about the status object returned by the restore function.\n",
            "WARNING:tensorflow:Value in checkpoint could not be found in the restored object: (root).keras_api.metrics.0.total\n",
            "WARNING:tensorflow:Value in checkpoint could not be found in the restored object: (root).keras_api.metrics.0.count\n",
            "WARNING:tensorflow:Value in checkpoint could not be found in the restored object: (root).keras_api.metrics.1.total\n",
            "WARNING:tensorflow:Value in checkpoint could not be found in the restored object: (root).keras_api.metrics.1.count\n",
            "WARNING:tensorflow:Detecting that an object or model or tf.train.Checkpoint is being deleted with unrestored values. See the following logs for the specific values in question. To silence these warnings, use `status.expect_partial()`. See https://www.tensorflow.org/api_docs/python/tf/train/Checkpoint#restorefor details about the status object returned by the restore function.\n",
            "WARNING:tensorflow:Value in checkpoint could not be found in the restored object: (root).keras_api.metrics.0.total\n",
            "WARNING:tensorflow:Value in checkpoint could not be found in the restored object: (root).keras_api.metrics.0.count\n",
            "WARNING:tensorflow:Value in checkpoint could not be found in the restored object: (root).keras_api.metrics.1.total\n",
            "WARNING:tensorflow:Value in checkpoint could not be found in the restored object: (root).keras_api.metrics.1.count\n",
            "WARNING:tensorflow:Layer lstm will not use cuDNN kernels since it doesn't meet the criteria. It will use a generic GPU kernel as fallback when running on GPU.\n",
            "/usr/local/lib/python3.10/dist-packages/scikeras/wrappers.py:915: UserWarning: ``build_fn`` will be renamed to ``model`` in a future release, at which point use of ``build_fn`` will raise an Error instead.\n",
            "  X, y = self._initialize(X, y)\n",
            "WARNING:tensorflow:Layer lstm will not use cuDNN kernels since it doesn't meet the criteria. It will use a generic GPU kernel as fallback when running on GPU.\n",
            "/usr/local/lib/python3.10/dist-packages/scikeras/wrappers.py:915: UserWarning: ``build_fn`` will be renamed to ``model`` in a future release, at which point use of ``build_fn`` will raise an Error instead.\n",
            "  X, y = self._initialize(X, y)\n",
            "WARNING:tensorflow:Layer lstm will not use cuDNN kernels since it doesn't meet the criteria. It will use a generic GPU kernel as fallback when running on GPU.\n",
            "/usr/local/lib/python3.10/dist-packages/scikeras/wrappers.py:915: UserWarning: ``build_fn`` will be renamed to ``model`` in a future release, at which point use of ``build_fn`` will raise an Error instead.\n",
            "  X, y = self._initialize(X, y)\n",
            "WARNING:tensorflow:Detecting that an object or model or tf.train.Checkpoint is being deleted with unrestored values. See the following logs for the specific values in question. To silence these warnings, use `status.expect_partial()`. See https://www.tensorflow.org/api_docs/python/tf/train/Checkpoint#restorefor details about the status object returned by the restore function.\n",
            "WARNING:tensorflow:Value in checkpoint could not be found in the restored object: (root).keras_api.metrics.0.total\n",
            "WARNING:tensorflow:Value in checkpoint could not be found in the restored object: (root).keras_api.metrics.0.count\n",
            "WARNING:tensorflow:Value in checkpoint could not be found in the restored object: (root).keras_api.metrics.1.total\n",
            "WARNING:tensorflow:Value in checkpoint could not be found in the restored object: (root).keras_api.metrics.1.count\n",
            "WARNING:tensorflow:Detecting that an object or model or tf.train.Checkpoint is being deleted with unrestored values. See the following logs for the specific values in question. To silence these warnings, use `status.expect_partial()`. See https://www.tensorflow.org/api_docs/python/tf/train/Checkpoint#restorefor details about the status object returned by the restore function.\n",
            "WARNING:tensorflow:Value in checkpoint could not be found in the restored object: (root).keras_api.metrics.0.total\n",
            "WARNING:tensorflow:Value in checkpoint could not be found in the restored object: (root).keras_api.metrics.0.count\n",
            "WARNING:tensorflow:Value in checkpoint could not be found in the restored object: (root).keras_api.metrics.1.total\n",
            "WARNING:tensorflow:Value in checkpoint could not be found in the restored object: (root).keras_api.metrics.1.count\n",
            "WARNING:tensorflow:Detecting that an object or model or tf.train.Checkpoint is being deleted with unrestored values. See the following logs for the specific values in question. To silence these warnings, use `status.expect_partial()`. See https://www.tensorflow.org/api_docs/python/tf/train/Checkpoint#restorefor details about the status object returned by the restore function.\n",
            "WARNING:tensorflow:Value in checkpoint could not be found in the restored object: (root).keras_api.metrics.0.total\n",
            "WARNING:tensorflow:Value in checkpoint could not be found in the restored object: (root).keras_api.metrics.0.count\n",
            "WARNING:tensorflow:Value in checkpoint could not be found in the restored object: (root).keras_api.metrics.1.total\n",
            "WARNING:tensorflow:Value in checkpoint could not be found in the restored object: (root).keras_api.metrics.1.count\n",
            "WARNING:tensorflow:Layer lstm will not use cuDNN kernels since it doesn't meet the criteria. It will use a generic GPU kernel as fallback when running on GPU.\n",
            "/usr/local/lib/python3.10/dist-packages/scikeras/wrappers.py:915: UserWarning: ``build_fn`` will be renamed to ``model`` in a future release, at which point use of ``build_fn`` will raise an Error instead.\n",
            "  X, y = self._initialize(X, y)\n",
            "WARNING:tensorflow:Layer lstm will not use cuDNN kernels since it doesn't meet the criteria. It will use a generic GPU kernel as fallback when running on GPU.\n",
            "/usr/local/lib/python3.10/dist-packages/scikeras/wrappers.py:915: UserWarning: ``build_fn`` will be renamed to ``model`` in a future release, at which point use of ``build_fn`` will raise an Error instead.\n",
            "  X, y = self._initialize(X, y)\n",
            "WARNING:tensorflow:Layer lstm will not use cuDNN kernels since it doesn't meet the criteria. It will use a generic GPU kernel as fallback when running on GPU.\n",
            "WARNING:tensorflow:Detecting that an object or model or tf.train.Checkpoint is being deleted with unrestored values. See the following logs for the specific values in question. To silence these warnings, use `status.expect_partial()`. See https://www.tensorflow.org/api_docs/python/tf/train/Checkpoint#restorefor details about the status object returned by the restore function.\n",
            "WARNING:tensorflow:Value in checkpoint could not be found in the restored object: (root).keras_api.metrics.0.total\n",
            "WARNING:tensorflow:Value in checkpoint could not be found in the restored object: (root).keras_api.metrics.0.count\n",
            "WARNING:tensorflow:Value in checkpoint could not be found in the restored object: (root).keras_api.metrics.1.total\n",
            "WARNING:tensorflow:Value in checkpoint could not be found in the restored object: (root).keras_api.metrics.1.count\n",
            "WARNING:tensorflow:Detecting that an object or model or tf.train.Checkpoint is being deleted with unrestored values. See the following logs for the specific values in question. To silence these warnings, use `status.expect_partial()`. See https://www.tensorflow.org/api_docs/python/tf/train/Checkpoint#restorefor details about the status object returned by the restore function.\n",
            "WARNING:tensorflow:Value in checkpoint could not be found in the restored object: (root).keras_api.metrics.0.total\n",
            "WARNING:tensorflow:Value in checkpoint could not be found in the restored object: (root).keras_api.metrics.0.count\n",
            "WARNING:tensorflow:Value in checkpoint could not be found in the restored object: (root).keras_api.metrics.1.total\n",
            "WARNING:tensorflow:Value in checkpoint could not be found in the restored object: (root).keras_api.metrics.1.count\n",
            "/usr/local/lib/python3.10/dist-packages/scikeras/wrappers.py:915: UserWarning: ``build_fn`` will be renamed to ``model`` in a future release, at which point use of ``build_fn`` will raise an Error instead.\n",
            "  X, y = self._initialize(X, y)\n",
            "WARNING:tensorflow:Layer lstm will not use cuDNN kernels since it doesn't meet the criteria. It will use a generic GPU kernel as fallback when running on GPU.\n",
            "/usr/local/lib/python3.10/dist-packages/scikeras/wrappers.py:915: UserWarning: ``build_fn`` will be renamed to ``model`` in a future release, at which point use of ``build_fn`` will raise an Error instead.\n",
            "  X, y = self._initialize(X, y)\n",
            "WARNING:tensorflow:Layer lstm will not use cuDNN kernels since it doesn't meet the criteria. It will use a generic GPU kernel as fallback when running on GPU.\n",
            "/usr/local/lib/python3.10/dist-packages/scikeras/wrappers.py:915: UserWarning: ``build_fn`` will be renamed to ``model`` in a future release, at which point use of ``build_fn`` will raise an Error instead.\n",
            "  X, y = self._initialize(X, y)\n",
            "WARNING:tensorflow:Detecting that an object or model or tf.train.Checkpoint is being deleted with unrestored values. See the following logs for the specific values in question. To silence these warnings, use `status.expect_partial()`. See https://www.tensorflow.org/api_docs/python/tf/train/Checkpoint#restorefor details about the status object returned by the restore function.\n",
            "WARNING:tensorflow:Value in checkpoint could not be found in the restored object: (root).keras_api.metrics.0.total\n",
            "WARNING:tensorflow:Value in checkpoint could not be found in the restored object: (root).keras_api.metrics.0.count\n",
            "WARNING:tensorflow:Value in checkpoint could not be found in the restored object: (root).keras_api.metrics.1.total\n",
            "WARNING:tensorflow:Value in checkpoint could not be found in the restored object: (root).keras_api.metrics.1.count\n",
            "WARNING:tensorflow:Detecting that an object or model or tf.train.Checkpoint is being deleted with unrestored values. See the following logs for the specific values in question. To silence these warnings, use `status.expect_partial()`. See https://www.tensorflow.org/api_docs/python/tf/train/Checkpoint#restorefor details about the status object returned by the restore function.\n",
            "WARNING:tensorflow:Value in checkpoint could not be found in the restored object: (root).keras_api.metrics.0.total\n",
            "WARNING:tensorflow:Value in checkpoint could not be found in the restored object: (root).keras_api.metrics.0.count\n",
            "WARNING:tensorflow:Value in checkpoint could not be found in the restored object: (root).keras_api.metrics.1.total\n",
            "WARNING:tensorflow:Value in checkpoint could not be found in the restored object: (root).keras_api.metrics.1.count\n",
            "WARNING:tensorflow:Detecting that an object or model or tf.train.Checkpoint is being deleted with unrestored values. See the following logs for the specific values in question. To silence these warnings, use `status.expect_partial()`. See https://www.tensorflow.org/api_docs/python/tf/train/Checkpoint#restorefor details about the status object returned by the restore function.\n",
            "WARNING:tensorflow:Value in checkpoint could not be found in the restored object: (root).keras_api.metrics.0.total\n",
            "WARNING:tensorflow:Value in checkpoint could not be found in the restored object: (root).keras_api.metrics.0.count\n",
            "WARNING:tensorflow:Value in checkpoint could not be found in the restored object: (root).keras_api.metrics.1.total\n",
            "WARNING:tensorflow:Value in checkpoint could not be found in the restored object: (root).keras_api.metrics.1.count\n",
            "WARNING:tensorflow:Layer lstm will not use cuDNN kernels since it doesn't meet the criteria. It will use a generic GPU kernel as fallback when running on GPU.\n",
            "/usr/local/lib/python3.10/dist-packages/scikeras/wrappers.py:915: UserWarning: ``build_fn`` will be renamed to ``model`` in a future release, at which point use of ``build_fn`` will raise an Error instead.\n",
            "  X, y = self._initialize(X, y)\n",
            "WARNING:tensorflow:Layer lstm will not use cuDNN kernels since it doesn't meet the criteria. It will use a generic GPU kernel as fallback when running on GPU.\n",
            "/usr/local/lib/python3.10/dist-packages/scikeras/wrappers.py:915: UserWarning: ``build_fn`` will be renamed to ``model`` in a future release, at which point use of ``build_fn`` will raise an Error instead.\n",
            "  X, y = self._initialize(X, y)\n",
            "WARNING:tensorflow:Layer lstm will not use cuDNN kernels since it doesn't meet the criteria. It will use a generic GPU kernel as fallback when running on GPU.\n",
            "/usr/local/lib/python3.10/dist-packages/scikeras/wrappers.py:915: UserWarning: ``build_fn`` will be renamed to ``model`` in a future release, at which point use of ``build_fn`` will raise an Error instead.\n",
            "  X, y = self._initialize(X, y)\n",
            "WARNING:tensorflow:Detecting that an object or model or tf.train.Checkpoint is being deleted with unrestored values. See the following logs for the specific values in question. To silence these warnings, use `status.expect_partial()`. See https://www.tensorflow.org/api_docs/python/tf/train/Checkpoint#restorefor details about the status object returned by the restore function.\n",
            "WARNING:tensorflow:Value in checkpoint could not be found in the restored object: (root).keras_api.metrics.0.total\n",
            "WARNING:tensorflow:Value in checkpoint could not be found in the restored object: (root).keras_api.metrics.0.count\n",
            "WARNING:tensorflow:Value in checkpoint could not be found in the restored object: (root).keras_api.metrics.1.total\n",
            "WARNING:tensorflow:Value in checkpoint could not be found in the restored object: (root).keras_api.metrics.1.count\n",
            "WARNING:tensorflow:Detecting that an object or model or tf.train.Checkpoint is being deleted with unrestored values. See the following logs for the specific values in question. To silence these warnings, use `status.expect_partial()`. See https://www.tensorflow.org/api_docs/python/tf/train/Checkpoint#restorefor details about the status object returned by the restore function.\n",
            "WARNING:tensorflow:Value in checkpoint could not be found in the restored object: (root).keras_api.metrics.0.total\n",
            "WARNING:tensorflow:Value in checkpoint could not be found in the restored object: (root).keras_api.metrics.0.count\n",
            "WARNING:tensorflow:Value in checkpoint could not be found in the restored object: (root).keras_api.metrics.1.total\n",
            "WARNING:tensorflow:Value in checkpoint could not be found in the restored object: (root).keras_api.metrics.1.count\n",
            "WARNING:tensorflow:Detecting that an object or model or tf.train.Checkpoint is being deleted with unrestored values. See the following logs for the specific values in question. To silence these warnings, use `status.expect_partial()`. See https://www.tensorflow.org/api_docs/python/tf/train/Checkpoint#restorefor details about the status object returned by the restore function.\n",
            "WARNING:tensorflow:Value in checkpoint could not be found in the restored object: (root).keras_api.metrics.0.total\n",
            "WARNING:tensorflow:Value in checkpoint could not be found in the restored object: (root).keras_api.metrics.0.count\n",
            "WARNING:tensorflow:Value in checkpoint could not be found in the restored object: (root).keras_api.metrics.1.total\n",
            "WARNING:tensorflow:Value in checkpoint could not be found in the restored object: (root).keras_api.metrics.1.count\n",
            "WARNING:tensorflow:Layer lstm will not use cuDNN kernels since it doesn't meet the criteria. It will use a generic GPU kernel as fallback when running on GPU.\n",
            "/usr/local/lib/python3.10/dist-packages/scikeras/wrappers.py:915: UserWarning: ``build_fn`` will be renamed to ``model`` in a future release, at which point use of ``build_fn`` will raise an Error instead.\n",
            "  X, y = self._initialize(X, y)\n",
            "WARNING:tensorflow:Layer lstm will not use cuDNN kernels since it doesn't meet the criteria. It will use a generic GPU kernel as fallback when running on GPU.\n",
            "/usr/local/lib/python3.10/dist-packages/scikeras/wrappers.py:915: UserWarning: ``build_fn`` will be renamed to ``model`` in a future release, at which point use of ``build_fn`` will raise an Error instead.\n",
            "  X, y = self._initialize(X, y)\n",
            "WARNING:tensorflow:Layer lstm will not use cuDNN kernels since it doesn't meet the criteria. It will use a generic GPU kernel as fallback when running on GPU.\n",
            "/usr/local/lib/python3.10/dist-packages/scikeras/wrappers.py:915: UserWarning: ``build_fn`` will be renamed to ``model`` in a future release, at which point use of ``build_fn`` will raise an Error instead.\n",
            "  X, y = self._initialize(X, y)\n",
            "WARNING:tensorflow:Detecting that an object or model or tf.train.Checkpoint is being deleted with unrestored values. See the following logs for the specific values in question. To silence these warnings, use `status.expect_partial()`. See https://www.tensorflow.org/api_docs/python/tf/train/Checkpoint#restorefor details about the status object returned by the restore function.\n",
            "WARNING:tensorflow:Value in checkpoint could not be found in the restored object: (root).keras_api.metrics.0.total\n",
            "WARNING:tensorflow:Value in checkpoint could not be found in the restored object: (root).keras_api.metrics.0.count\n",
            "WARNING:tensorflow:Value in checkpoint could not be found in the restored object: (root).keras_api.metrics.1.total\n",
            "WARNING:tensorflow:Value in checkpoint could not be found in the restored object: (root).keras_api.metrics.1.count\n",
            "WARNING:tensorflow:Detecting that an object or model or tf.train.Checkpoint is being deleted with unrestored values. See the following logs for the specific values in question. To silence these warnings, use `status.expect_partial()`. See https://www.tensorflow.org/api_docs/python/tf/train/Checkpoint#restorefor details about the status object returned by the restore function.\n",
            "WARNING:tensorflow:Value in checkpoint could not be found in the restored object: (root).keras_api.metrics.0.total\n",
            "WARNING:tensorflow:Value in checkpoint could not be found in the restored object: (root).keras_api.metrics.0.count\n",
            "WARNING:tensorflow:Value in checkpoint could not be found in the restored object: (root).keras_api.metrics.1.total\n",
            "WARNING:tensorflow:Value in checkpoint could not be found in the restored object: (root).keras_api.metrics.1.count\n",
            "WARNING:tensorflow:Detecting that an object or model or tf.train.Checkpoint is being deleted with unrestored values. See the following logs for the specific values in question. To silence these warnings, use `status.expect_partial()`. See https://www.tensorflow.org/api_docs/python/tf/train/Checkpoint#restorefor details about the status object returned by the restore function.\n",
            "WARNING:tensorflow:Value in checkpoint could not be found in the restored object: (root).keras_api.metrics.0.total\n",
            "WARNING:tensorflow:Value in checkpoint could not be found in the restored object: (root).keras_api.metrics.0.count\n",
            "WARNING:tensorflow:Value in checkpoint could not be found in the restored object: (root).keras_api.metrics.1.total\n",
            "WARNING:tensorflow:Value in checkpoint could not be found in the restored object: (root).keras_api.metrics.1.count\n",
            "WARNING:tensorflow:Layer lstm will not use cuDNN kernels since it doesn't meet the criteria. It will use a generic GPU kernel as fallback when running on GPU.\n",
            "/usr/local/lib/python3.10/dist-packages/scikeras/wrappers.py:915: UserWarning: ``build_fn`` will be renamed to ``model`` in a future release, at which point use of ``build_fn`` will raise an Error instead.\n",
            "  X, y = self._initialize(X, y)\n",
            "WARNING:tensorflow:Layer lstm will not use cuDNN kernels since it doesn't meet the criteria. It will use a generic GPU kernel as fallback when running on GPU.\n",
            "/usr/local/lib/python3.10/dist-packages/scikeras/wrappers.py:915: UserWarning: ``build_fn`` will be renamed to ``model`` in a future release, at which point use of ``build_fn`` will raise an Error instead.\n",
            "  X, y = self._initialize(X, y)\n",
            "WARNING:tensorflow:Layer lstm will not use cuDNN kernels since it doesn't meet the criteria. It will use a generic GPU kernel as fallback when running on GPU.\n",
            "WARNING:tensorflow:Detecting that an object or model or tf.train.Checkpoint is being deleted with unrestored values. See the following logs for the specific values in question. To silence these warnings, use `status.expect_partial()`. See https://www.tensorflow.org/api_docs/python/tf/train/Checkpoint#restorefor details about the status object returned by the restore function.\n",
            "WARNING:tensorflow:Value in checkpoint could not be found in the restored object: (root).keras_api.metrics.0.total\n",
            "WARNING:tensorflow:Value in checkpoint could not be found in the restored object: (root).keras_api.metrics.0.count\n",
            "WARNING:tensorflow:Value in checkpoint could not be found in the restored object: (root).keras_api.metrics.1.total\n",
            "WARNING:tensorflow:Value in checkpoint could not be found in the restored object: (root).keras_api.metrics.1.count\n",
            "WARNING:tensorflow:Detecting that an object or model or tf.train.Checkpoint is being deleted with unrestored values. See the following logs for the specific values in question. To silence these warnings, use `status.expect_partial()`. See https://www.tensorflow.org/api_docs/python/tf/train/Checkpoint#restorefor details about the status object returned by the restore function.\n",
            "WARNING:tensorflow:Value in checkpoint could not be found in the restored object: (root).keras_api.metrics.0.total\n",
            "WARNING:tensorflow:Value in checkpoint could not be found in the restored object: (root).keras_api.metrics.0.count\n",
            "WARNING:tensorflow:Value in checkpoint could not be found in the restored object: (root).keras_api.metrics.1.total\n",
            "WARNING:tensorflow:Value in checkpoint could not be found in the restored object: (root).keras_api.metrics.1.count\n",
            "/usr/local/lib/python3.10/dist-packages/scikeras/wrappers.py:915: UserWarning: ``build_fn`` will be renamed to ``model`` in a future release, at which point use of ``build_fn`` will raise an Error instead.\n",
            "  X, y = self._initialize(X, y)\n",
            "WARNING:tensorflow:Layer lstm will not use cuDNN kernels since it doesn't meet the criteria. It will use a generic GPU kernel as fallback when running on GPU.\n",
            "/usr/local/lib/python3.10/dist-packages/scikeras/wrappers.py:915: UserWarning: ``build_fn`` will be renamed to ``model`` in a future release, at which point use of ``build_fn`` will raise an Error instead.\n",
            "  X, y = self._initialize(X, y)\n",
            "WARNING:tensorflow:Layer lstm will not use cuDNN kernels since it doesn't meet the criteria. It will use a generic GPU kernel as fallback when running on GPU.\n",
            "/usr/local/lib/python3.10/dist-packages/scikeras/wrappers.py:915: UserWarning: ``build_fn`` will be renamed to ``model`` in a future release, at which point use of ``build_fn`` will raise an Error instead.\n",
            "  X, y = self._initialize(X, y)\n",
            "WARNING:tensorflow:Detecting that an object or model or tf.train.Checkpoint is being deleted with unrestored values. See the following logs for the specific values in question. To silence these warnings, use `status.expect_partial()`. See https://www.tensorflow.org/api_docs/python/tf/train/Checkpoint#restorefor details about the status object returned by the restore function.\n",
            "WARNING:tensorflow:Value in checkpoint could not be found in the restored object: (root).keras_api.metrics.0.total\n",
            "WARNING:tensorflow:Value in checkpoint could not be found in the restored object: (root).keras_api.metrics.0.count\n",
            "WARNING:tensorflow:Value in checkpoint could not be found in the restored object: (root).keras_api.metrics.1.total\n",
            "WARNING:tensorflow:Value in checkpoint could not be found in the restored object: (root).keras_api.metrics.1.count\n",
            "WARNING:tensorflow:Detecting that an object or model or tf.train.Checkpoint is being deleted with unrestored values. See the following logs for the specific values in question. To silence these warnings, use `status.expect_partial()`. See https://www.tensorflow.org/api_docs/python/tf/train/Checkpoint#restorefor details about the status object returned by the restore function.\n",
            "WARNING:tensorflow:Value in checkpoint could not be found in the restored object: (root).keras_api.metrics.0.total\n",
            "WARNING:tensorflow:Value in checkpoint could not be found in the restored object: (root).keras_api.metrics.0.count\n",
            "WARNING:tensorflow:Value in checkpoint could not be found in the restored object: (root).keras_api.metrics.1.total\n",
            "WARNING:tensorflow:Value in checkpoint could not be found in the restored object: (root).keras_api.metrics.1.count\n",
            "WARNING:tensorflow:Detecting that an object or model or tf.train.Checkpoint is being deleted with unrestored values. See the following logs for the specific values in question. To silence these warnings, use `status.expect_partial()`. See https://www.tensorflow.org/api_docs/python/tf/train/Checkpoint#restorefor details about the status object returned by the restore function.\n",
            "WARNING:tensorflow:Value in checkpoint could not be found in the restored object: (root).keras_api.metrics.0.total\n",
            "WARNING:tensorflow:Value in checkpoint could not be found in the restored object: (root).keras_api.metrics.0.count\n",
            "WARNING:tensorflow:Value in checkpoint could not be found in the restored object: (root).keras_api.metrics.1.total\n",
            "WARNING:tensorflow:Value in checkpoint could not be found in the restored object: (root).keras_api.metrics.1.count\n",
            "WARNING:tensorflow:Layer lstm will not use cuDNN kernels since it doesn't meet the criteria. It will use a generic GPU kernel as fallback when running on GPU.\n",
            "/usr/local/lib/python3.10/dist-packages/scikeras/wrappers.py:915: UserWarning: ``build_fn`` will be renamed to ``model`` in a future release, at which point use of ``build_fn`` will raise an Error instead.\n",
            "  X, y = self._initialize(X, y)\n"
          ]
        },
        {
          "output_type": "error",
          "ename": "ValueError",
          "evalue": "ignored",
          "traceback": [
            "\u001b[0;31m---------------------------------------------------------------------------\u001b[0m",
            "\u001b[0;31mValueError\u001b[0m                                Traceback (most recent call last)",
            "\u001b[0;32m<ipython-input-8-0dcdfe3600e0>\u001b[0m in \u001b[0;36m<cell line: 9>\u001b[0;34m()\u001b[0m\n\u001b[1;32m      7\u001b[0m \u001b[0;32mfrom\u001b[0m \u001b[0msklearn\u001b[0m\u001b[0;34m.\u001b[0m\u001b[0mmodel_selection\u001b[0m \u001b[0;32mimport\u001b[0m \u001b[0mGridSearchCV\u001b[0m\u001b[0;34m\u001b[0m\u001b[0;34m\u001b[0m\u001b[0m\n\u001b[1;32m      8\u001b[0m \u001b[0mgrid\u001b[0m \u001b[0;34m=\u001b[0m \u001b[0mGridSearchCV\u001b[0m\u001b[0;34m(\u001b[0m\u001b[0mestimator\u001b[0m\u001b[0;34m=\u001b[0m\u001b[0mmodel\u001b[0m\u001b[0;34m,\u001b[0m \u001b[0mparam_grid\u001b[0m\u001b[0;34m=\u001b[0m\u001b[0mparam_grid\u001b[0m\u001b[0;34m)\u001b[0m\u001b[0;34m\u001b[0m\u001b[0;34m\u001b[0m\u001b[0m\n\u001b[0;32m----> 9\u001b[0;31m \u001b[0mgrid_result\u001b[0m \u001b[0;34m=\u001b[0m \u001b[0mgrid\u001b[0m\u001b[0;34m.\u001b[0m\u001b[0mfit\u001b[0m\u001b[0;34m(\u001b[0m\u001b[0mX_train\u001b[0m\u001b[0;34m,\u001b[0m \u001b[0mY_train\u001b[0m\u001b[0;34m)\u001b[0m\u001b[0;34m\u001b[0m\u001b[0;34m\u001b[0m\u001b[0m\n\u001b[0m\u001b[1;32m     10\u001b[0m \u001b[0;31m# summarize results\u001b[0m\u001b[0;34m\u001b[0m\u001b[0;34m\u001b[0m\u001b[0m\n\u001b[1;32m     11\u001b[0m \u001b[0mprint\u001b[0m\u001b[0;34m(\u001b[0m\u001b[0;34m\"Best: %f using %s\"\u001b[0m \u001b[0;34m%\u001b[0m \u001b[0;34m(\u001b[0m\u001b[0mgrid_result\u001b[0m\u001b[0;34m.\u001b[0m\u001b[0mbest_score_\u001b[0m\u001b[0;34m,\u001b[0m \u001b[0mgrid_result\u001b[0m\u001b[0;34m.\u001b[0m\u001b[0mbest_params_\u001b[0m\u001b[0;34m)\u001b[0m\u001b[0;34m)\u001b[0m\u001b[0;34m\u001b[0m\u001b[0;34m\u001b[0m\u001b[0m\n",
            "\u001b[0;32m/usr/local/lib/python3.10/dist-packages/sklearn/model_selection/_search.py\u001b[0m in \u001b[0;36mfit\u001b[0;34m(self, X, y, groups, **fit_params)\u001b[0m\n\u001b[1;32m    872\u001b[0m                 \u001b[0;32mreturn\u001b[0m \u001b[0mresults\u001b[0m\u001b[0;34m\u001b[0m\u001b[0;34m\u001b[0m\u001b[0m\n\u001b[1;32m    873\u001b[0m \u001b[0;34m\u001b[0m\u001b[0m\n\u001b[0;32m--> 874\u001b[0;31m             \u001b[0mself\u001b[0m\u001b[0;34m.\u001b[0m\u001b[0m_run_search\u001b[0m\u001b[0;34m(\u001b[0m\u001b[0mevaluate_candidates\u001b[0m\u001b[0;34m)\u001b[0m\u001b[0;34m\u001b[0m\u001b[0;34m\u001b[0m\u001b[0m\n\u001b[0m\u001b[1;32m    875\u001b[0m \u001b[0;34m\u001b[0m\u001b[0m\n\u001b[1;32m    876\u001b[0m             \u001b[0;31m# multimetric is determined here because in the case of a callable\u001b[0m\u001b[0;34m\u001b[0m\u001b[0;34m\u001b[0m\u001b[0m\n",
            "\u001b[0;32m/usr/local/lib/python3.10/dist-packages/sklearn/model_selection/_search.py\u001b[0m in \u001b[0;36m_run_search\u001b[0;34m(self, evaluate_candidates)\u001b[0m\n\u001b[1;32m   1386\u001b[0m     \u001b[0;32mdef\u001b[0m \u001b[0m_run_search\u001b[0m\u001b[0;34m(\u001b[0m\u001b[0mself\u001b[0m\u001b[0;34m,\u001b[0m \u001b[0mevaluate_candidates\u001b[0m\u001b[0;34m)\u001b[0m\u001b[0;34m:\u001b[0m\u001b[0;34m\u001b[0m\u001b[0;34m\u001b[0m\u001b[0m\n\u001b[1;32m   1387\u001b[0m         \u001b[0;34m\"\"\"Search all candidates in param_grid\"\"\"\u001b[0m\u001b[0;34m\u001b[0m\u001b[0;34m\u001b[0m\u001b[0m\n\u001b[0;32m-> 1388\u001b[0;31m         \u001b[0mevaluate_candidates\u001b[0m\u001b[0;34m(\u001b[0m\u001b[0mParameterGrid\u001b[0m\u001b[0;34m(\u001b[0m\u001b[0mself\u001b[0m\u001b[0;34m.\u001b[0m\u001b[0mparam_grid\u001b[0m\u001b[0;34m)\u001b[0m\u001b[0;34m)\u001b[0m\u001b[0;34m\u001b[0m\u001b[0;34m\u001b[0m\u001b[0m\n\u001b[0m\u001b[1;32m   1389\u001b[0m \u001b[0;34m\u001b[0m\u001b[0m\n\u001b[1;32m   1390\u001b[0m \u001b[0;34m\u001b[0m\u001b[0m\n",
            "\u001b[0;32m/usr/local/lib/python3.10/dist-packages/sklearn/model_selection/_search.py\u001b[0m in \u001b[0;36mevaluate_candidates\u001b[0;34m(candidate_params, cv, more_results)\u001b[0m\n\u001b[1;32m    849\u001b[0m                     )\n\u001b[1;32m    850\u001b[0m \u001b[0;34m\u001b[0m\u001b[0m\n\u001b[0;32m--> 851\u001b[0;31m                 \u001b[0m_warn_or_raise_about_fit_failures\u001b[0m\u001b[0;34m(\u001b[0m\u001b[0mout\u001b[0m\u001b[0;34m,\u001b[0m \u001b[0mself\u001b[0m\u001b[0;34m.\u001b[0m\u001b[0merror_score\u001b[0m\u001b[0;34m)\u001b[0m\u001b[0;34m\u001b[0m\u001b[0;34m\u001b[0m\u001b[0m\n\u001b[0m\u001b[1;32m    852\u001b[0m \u001b[0;34m\u001b[0m\u001b[0m\n\u001b[1;32m    853\u001b[0m                 \u001b[0;31m# For callable self.scoring, the return type is only know after\u001b[0m\u001b[0;34m\u001b[0m\u001b[0;34m\u001b[0m\u001b[0m\n",
            "\u001b[0;32m/usr/local/lib/python3.10/dist-packages/sklearn/model_selection/_validation.py\u001b[0m in \u001b[0;36m_warn_or_raise_about_fit_failures\u001b[0;34m(results, error_score)\u001b[0m\n\u001b[1;32m    365\u001b[0m                 \u001b[0;34mf\"Below are more details about the failures:\\n{fit_errors_summary}\"\u001b[0m\u001b[0;34m\u001b[0m\u001b[0;34m\u001b[0m\u001b[0m\n\u001b[1;32m    366\u001b[0m             )\n\u001b[0;32m--> 367\u001b[0;31m             \u001b[0;32mraise\u001b[0m \u001b[0mValueError\u001b[0m\u001b[0;34m(\u001b[0m\u001b[0mall_fits_failed_message\u001b[0m\u001b[0;34m)\u001b[0m\u001b[0;34m\u001b[0m\u001b[0;34m\u001b[0m\u001b[0m\n\u001b[0m\u001b[1;32m    368\u001b[0m \u001b[0;34m\u001b[0m\u001b[0m\n\u001b[1;32m    369\u001b[0m         \u001b[0;32melse\u001b[0m\u001b[0;34m:\u001b[0m\u001b[0;34m\u001b[0m\u001b[0;34m\u001b[0m\u001b[0m\n",
            "\u001b[0;31mValueError\u001b[0m: \nAll the 45 fits failed.\nIt is very likely that your model is misconfigured.\nYou can try to debug the error by setting error_score='raise'.\n\nBelow are more details about the failures:\n--------------------------------------------------------------------------------\n45 fits failed with the following error:\nTraceback (most recent call last):\n  File \"/usr/local/lib/python3.10/dist-packages/sklearn/model_selection/_validation.py\", line 686, in _fit_and_score\n    estimator.fit(X_train, y_train, **fit_params)\n  File \"/usr/local/lib/python3.10/dist-packages/scikeras/wrappers.py\", line 1491, in fit\n    super().fit(X=X, y=y, sample_weight=sample_weight, **kwargs)\n  File \"/usr/local/lib/python3.10/dist-packages/scikeras/wrappers.py\", line 760, in fit\n    self._fit(\n  File \"/usr/local/lib/python3.10/dist-packages/scikeras/wrappers.py\", line 915, in _fit\n    X, y = self._initialize(X, y)\n  File \"/usr/local/lib/python3.10/dist-packages/scikeras/wrappers.py\", line 852, in _initialize\n    self.model_ = self._build_keras_model()\n  File \"/usr/local/lib/python3.10/dist-packages/scikeras/wrappers.py\", line 400, in _build_keras_model\n    final_build_fn = self._check_model_param()\n  File \"/usr/local/lib/python3.10/dist-packages/scikeras/wrappers.py\", line 325, in _check_model_param\n    raise TypeError(\nTypeError: ``model`` must be a callable, a Keras Model instance or None\n"
          ]
        }
      ]
    }
  ]
}